Workbook
Name Slicer_bulan: #N/A
Name Slicer_metode_pembayaran: #N/A
Name Slicer_tahun: #N/A

Sheet dashboard

Sheet README
A1: Dashboard Analisis Pembatalan & Retur: README
A3: Tujuan
A4: Mendeskripsikan pola order yang gagal menjadi revenue (Batal + Retur Penuh): tren bulanan, sumber & alasan pembatalan, serta keterkaitannya dengan metode pembayaran dan kategori produk. Jenis analisis: deskriptif dan diagnostik.
A6: Sumber data & alur
A7: RAW_PUBLIC_Dataset → data_cleaning.ipynb → Clean_data/master_clean_orders_FIXED.xlsx → 02_analysis.ipynb → Clean_data/analysis_dataset.xlsx → Power Query (q_orders) → tbl_orders → pivot → chart_data → dashboard.
A8: Refresh: Data > Refresh All. Path Power Query bersifat absolut; jika folder dipindah, ubah lewat Data > Queries & Connections > q_orders.
A10: Definisi
A11: Order settled: is_settled = 1 (status akhir sudah diketahui). 250 order 'Dalam Proses' (Nov 2025) dikeluarkan dari denominator.
A12: Gagal-Revenue Rate = (Batal + Retur Penuh) / order settled. Calculated field rate_gagal = is_gagal_revenue / is_settled.
A13: Sumber & Alasan memakai basis order batal (is_cancelled = 1); retur penuh tidak termasuk karena tidak punya alasan pembatalan.
A14: Metode & kategori hanya ditampilkan bila n ≥ 30 order settled (dihitung atas seluruh 23 bulan). Kategori: hanya order 1 kategori.
A16: Hubungan slicer
... A26: 6. Temuan menunjukkan keterkaitan antarvariabel dan tidak membuktikan hubungan sebab-akibat.

Sheet chart_data
A1: Tabel bantu chart & KPI. Semua angka diambil dari pivot (GETPIVOTDATA/INDEX); jangan diketik manual.
A3: KPI | B3: Nilai
A4: Total Order Settled | B4: =GETPIVOTDATA("Order Settled",pivot!$B$6) -> 20154 | C4: =TEXT(B4,"#,##0") -> 20,154
A5: Gagal-Revenue Rate | B5: =GETPIVOTDATA("Gagal Rate",pivot!$B$6) -> 0.14066687 | C5: =TEXT(B5,"0.00%") -> 14.07%
A6: Total Order Gagal | B6: =GETPIVOTDATA("Order Gagal",pivot!$B$6) -> 2835 | C6: =TEXT(B6,"#,##0") -> 2,835
A9: periode | B9: rate | C9: rate_bulan_lain | D9: rate_mei_2025 | E9: rata_rata
A10: 2024-01 | B10: =IFERROR(GETPIVOTDATA("Gagal Rate",pivot!$G$6,"bulan_file",A10),NA()) -> 0.14849188 | C10: =IF(A10="2025-05",NA(),B10) -> 0.14849188 | D10: =IF(A10="2025-05",B10,NA()) -> #N/A | E10: =GETPIVOTDATA("Gagal Rate",pivot!$G$6) -> 0.14066687
A11: 2024-02 | B11: =IFERROR(GETPIVOTDATA("Gagal Rate",pivot!$G$6,"bulan_file",A11),NA()) -> 0.16195373 | C11: =IF(A11="2025-05",NA(),B11) -> 0.16195373 | D11: =IF(A11="2025-05",B11,NA()) -> #N/A | E11: =GETPIVOTDATA("Gagal Rate",pivot!$G$6) -> 0.14066687
A12: 2024-03 | B12: =IFERROR(GETPIVOTDATA("Gagal Rate",pivot!$G$6,"bulan_file",A12),NA()) -> 0.14128035 | C12: =IF(A12="2025-05",NA(),B12) -> 0.14128035 | D12: =IF(A12="2025-05",B12,NA()) -> #N/A | E12: =GETPIVOTDATA("Gagal Rate",pivot!$G$6) -> 0.14066687
A13: 2024-04 | B13: =IFERROR(GETPIVOTDATA("Gagal Rate",pivot!$G$6,"bulan_file",A13),NA()) -> 0.18292683 | C13: =IF(A13="2025-05",NA(),B13) -> 0.18292683 | D13: =IF(A13="2025-05",B13,NA()) -> #N/A | E13: =GETPIVOTDATA("Gagal Rate",pivot!$G$6) -> 0.14066687
A14: 2024-05 | B14: =IFERROR(GETPIVOTDATA("Gagal Rate",pivot!$G$6,"bulan_file",A14),NA()) -> 0.15645161 | C14: =IF(A14="2025-05",NA(),B14) -> 0.15645161 | D14: =IF(A14="2025-05",B14,NA()) -> #N/A | E14: =GETPIVOTDATA("Gagal Rate",pivot!$G$6) -> 0.14066687
A15: 2024-06 | B15: =IFERROR(GETPIVOTDATA("Gagal Rate",pivot!$G$6,"bulan_file",A15),NA()) -> 0.1276901 | C15: =IF(A15="2025-05",NA(),B15) -> 0.1276901 | D15: =IF(A15="2025-05",B15,NA()) -> #N/A | E15: =GETPIVOTDATA("Gagal Rate",pivot!$G$6) -> 0.14066687
A16: 2024-07 | B16: =IFERROR(GETPIVOTDATA("Gagal Rate",pivot!$G$6,"bulan_file",A16),NA()) -> 0.12362205 | C16: =IF(A16="2025-05",NA(),B16) -> 0.12362205 | D16: =IF(A16="2025-05",B16,NA()) -> #N/A | E16: =GETPIVOTDATA("Gagal Rate",pivot!$G$6) -> 0.14066687
A17: 2024-08 | B17: =IFERROR(GETPIVOTDATA("Gagal Rate",pivot!$G$6,"bulan_file",A17),NA()) -> 0.15467904 | C17: =IF(A17="2025-05",NA(),B17) -> 0.15467904 | D17: =IF(A17="2025-05",B17,NA()) -> #N/A | E17: =GETPIVOTDATA("Gagal Rate",pivot!$G$6) -> 0.14066687
A18: 2024-09 | B18: =IFERROR(GETPIVOTDATA("Gagal Rate",pivot!$G$6,"bulan_file",A18),NA()) -> 0.14425646 | C18: =IF(A18="2025-05",NA(),B18) -> 0.14425646 | D18: =IF(A18="2025-05",B18,NA()) -> #N/A | E18: =GETPIVOTDATA("Gagal Rate",pivot!$G$6) -> 0.14066687
A19: 2024-10 | B19: =IFERROR(GETPIVOTDATA("Gagal Rate",pivot!$G$6,"bulan_file",A19),NA()) -> 0.13557929 | C19: =IF(A19="2025-05",NA(),B19) -> 0.13557929 | D19: =IF(A19="2025-05",B19,NA()) -> #N/A | E19: =GETPIVOTDATA("Gagal Rate",pivot!$G$6) -> 0.14066687
A20: 2024-11 | B20: =IFERROR(GETPIVOTDATA("Gagal Rate",pivot!$G$6,"bulan_file",A20),NA()) -> 0.14271938 | C20: =IF(A20="2025-05",NA(),B20) -> 0.14271938 | D20: =IF(A20="2025-05",B20,NA()) -> #N/A | E20: =GETPIVOTDATA("Gagal Rate",pivot!$G$6) -> 0.14066687
A21: 2024-12 | B21: =IFERROR(GETPIVOTDATA("Gagal Rate",pivot!$G$6,"bulan_file",A21),NA()) -> 0.14250412 | C21: =IF(A21="2025-05",NA(),B21) -> 0.14250412 | D21: =IF(A21="2025-05",B21,NA()) -> #N/A | E21: =GETPIVOTDATA("Gagal Rate",pivot!$G$6) -> 0.14066687
... A32: 2025-11 | B32: =IFERROR(GETPIVOTDATA("Gagal Rate",pivot!$G$6,"bulan_file",A32),NA()) -> 0.12372304 | C32: =IF(A32="2025-05",NA(),B32) -> 0.12372304 | D32: =IF(A32="2025-05",B32,NA()) -> #N/A | E32: =GETPIVOTDATA("Gagal Rate",pivot!$G$6) -> 0.14066687
A35: cancel_source | B35: order_batal
A36: Pembeli | B36: =IFERROR(GETPIVOTDATA("Order Batal",pivot!$M$6,"cancel_source",A36),0) -> 1844
A37: Sistem/Penjual (Otomatis) | B37: =IFERROR(GETPIVOTDATA("Order Batal",pivot!$M$6,"cancel_source",A37),0) -> 880
A38: Penjual (Manual) | B38: =IFERROR(GETPIVOTDATA("Order Batal",pivot!$M$6,"cancel_source",A38),0) -> 14
A39: Total order batal | B39: =SUM(B36:B38) -> 2738 | C39: ="Total: "&TEXT(B39,"#,##0")&" order batal" -> Total: 2,738 order batal
A42: label | B42: metode | C42: n_settled | D42: rate | E42: di_atas_rata2 | F42: di_bawah_rata2
A43: =B43 -> Indomaret/i.Saku | B43: =IFERROR(INDEX(pivot!$Q$7:$Q$16,1)&"","") -> Indomaret/i.Saku | C43: =IF(B43="","",INDEX(pivot!$R$7:$R$16,1)) -> 42 | D43: =IF(B43="",NA(),INDEX(pivot!$T$7:$T$16,1)) -> 0.5 | E43: =IF(ISNA(D43),NA(),IF(D43>$B$52,D43,NA())) -> 0.5 | F43: =IF(ISNA(D43),NA(),IF(D43<=$B$52,D43,NA())) -> #N/A
A44: =B44 -> Alfamart/Alfamidi/Dan+Dan | B44: =IFERROR(INDEX(pivot!$Q$7:$Q$16,2)&"","") -> Alfamart/Alfamidi/Dan+Dan | C44: =IF(B44="","",INDEX(pivot!$R$7:$R$16,2)) -> 35 | D44: =IF(B44="",NA(),INDEX(pivot!$T$7:$T$16,2)) -> 0.45714286 | E44: =IF(ISNA(D44),NA(),IF(D44>$B$52,D44,NA())) -> 0.45714286 | F44: =IF(ISNA(D44),NA(),IF(D44<=$B$52,D44,NA())) -> #N/A
A45: =B45 -> Online Payment | B45: =IFERROR(INDEX(pivot!$Q$7:$Q$16,3)&"","") -> Online Payment | C45: =IF(B45="","",INDEX(pivot!$R$7:$R$16,3)) -> 3079 | D45: =IF(B45="",NA(),INDEX(pivot!$T$7:$T$16,3)) -> 0.18934719 | E45: =IF(ISNA(D45),NA(),IF(D45>$B$52,D45,NA())) -> 0.18934719 | F45: =IF(ISNA(D45),NA(),IF(D45<=$B$52,D45,NA())) -> #N/A
A46: =B46 -> SPayLater | B46: =IFERROR(INDEX(pivot!$Q$7:$Q$16,4)&"","") -> SPayLater | C46: =IF(B46="","",INDEX(pivot!$R$7:$R$16,4)) -> 1443 | D46: =IF(B46="",NA(),INDEX(pivot!$T$7:$T$16,4)) -> 0.15592516 | E46: =IF(ISNA(D46),NA(),IF(D46>$B$52,D46,NA())) -> 0.15592516 | F46: =IF(ISNA(D46),NA(),IF(D46<=$B$52,D46,NA())) -> #N/A
A47: =B47 -> Kartu Kredit/Debit | B47: =IFERROR(INDEX(pivot!$Q$7:$Q$16,5)&"","") -> Kartu Kredit/Debit | C47: =IF(B47="","",INDEX(pivot!$R$7:$R$16,5)) -> 222 | D47: =IF(B47="",NA(),INDEX(pivot!$T$7:$T$16,5)) -> 0.14414414 | E47: =IF(ISNA(D47),NA(),IF(D47>$B$52,D47,NA())) -> 0.14414414 | F47: =IF(ISNA(D47),NA(),IF(D47<=$B$52,D47,NA())) -> #N/A
A48: =B48 -> COD (Bayar di Tempat) | B48: =IFERROR(INDEX(pivot!$Q$7:$Q$16,6)&"","") -> COD (Bayar di Tempat) | C48: =IF(B48="","",INDEX(pivot!$R$7:$R$16,6)) -> 11160 | D48: =IF(B48="",NA(),INDEX(pivot!$T$7:$T$16,6)) -> 0.13826165 | E48: =IF(ISNA(D48),NA(),IF(D48>$B$52,D48,NA())) -> #N/A | F48: =IF(ISNA(D48),NA(),IF(D48<=$B$52,D48,NA())) -> 0.13826165
A49: =B49 -> SeaBank Bayar Instan | B49: =IFERROR(INDEX(pivot!$Q$7:$Q$16,7)&"","") -> SeaBank Bayar Instan | C49: =IF(B49="","",INDEX(pivot!$R$7:$R$16,7)) -> 577 | D49: =IF(B49="",NA(),INDEX(pivot!$T$7:$T$16,7)) -> 0.13171577 | E49: =IF(ISNA(D49),NA(),IF(D49>$B$52,D49,NA())) -> #N/A | F49: =IF(ISNA(D49),NA(),IF(D49<=$B$52,D49,NA())) -> 0.13171577
A50: =B50 -> Saldo ShopeePay | B50: =IFERROR(INDEX(pivot!$Q$7:$Q$16,8)&"","") -> Saldo ShopeePay | C50: =IF(B50="","",INDEX(pivot!$R$7:$R$16,8)) -> 3571 | D50: =IF(B50="",NA(),INDEX(pivot!$T$7:$T$16,8)) -> 0.094091291 | E50: =IF(ISNA(D50),NA(),IF(D50>$B$52,D50,NA())) -> #N/A | F50: =IF(ISNA(D50),NA(),IF(D50<=$B$52,D50,NA())) -> 0.094091291
A52: Rata-rata (metode n>=30) | B52: =SUM(pivot!$S$7:$S$16)/SUM(pivot!$R$7:$R$16) -> 0.14069253
A55: label | B55: kategori | C55: n_settled | D55: rate
A56: =B56 -> Pengolah Bumbu / Sayur | B56: =IFERROR(INDEX(pivot!$W$7:$W$13,1)&"","") -> Pengolah Bumbu / Sayur | C56: =IF(B56="","",INDEX(pivot!$X$7:$X$13,1)) -> 155 | D56: =IF(B56="",NA(),INDEX(pivot!$Z$7:$Z$13,1)) -> 0.32258065
A57: =B57 -> Rak / Rak Serbaguna | B57: =IFERROR(INDEX(pivot!$W$7:$W$13,2)&"","") -> Rak / Rak Serbaguna | C57: =IF(B57="","",INDEX(pivot!$X$7:$X$13,2)) -> 568 | D57: =IF(B57="",NA(),INDEX(pivot!$Z$7:$Z$13,2)) -> 0.31866197
A58: =B58 -> Stempel / Alat Kantor | B58: =IFERROR(INDEX(pivot!$W$7:$W$13,3)&"","") -> Stempel / Alat Kantor | C58: =IF(B58="","",INDEX(pivot!$X$7:$X$13,3)) -> 117 | D58: =IF(B58="",NA(),INDEX(pivot!$Z$7:$Z$13,3)) -> 0.25641026
A59: =B59 -> Piring | B59: =IFERROR(INDEX(pivot!$W$7:$W$13,4)&"","") -> Piring | C59: =IF(B59="","",INDEX(pivot!$X$7:$X$13,4)) -> 141 | D59: =IF(B59="",NA(),INDEX(pivot!$Z$7:$Z$13,4)) -> 0.24822695
A60: =B60 -> Plastik / Wadah Plastik | B60: =IFERROR(INDEX(pivot!$W$7:$W$13,5)&"","") -> Plastik / Wadah Plastik | C60: =IF(B60="","",INDEX(pivot!$X$7:$X$13,5)) -> 107 | D60: =IF(B60="",NA(),INDEX(pivot!$Z$7:$Z$13,5)) -> 0.24299065
...

Sheet pivot
B1: Semua pivot memakai 1 pivot cache dari tbl_orders (syarat agar slicer bisa mengendalikan beberapa pivot).
B3: P1 KPI | G3: P2 Tren (tidak ikut slicer Tahun & Bulan) | M3: P3 Sumber pembatalan | Q3: P4 Metode (tidak ikut slicer Bulan & Metode) | W3: P5 Kategori top 5 (tidak ikut slicer Bulan) | AC3: P6 Alasan top 5
M4: is_cancelled | N4: 1 | AC4: is_cancelled | AD4: 1
B6: Order Settled | C6: Order Gagal | D6: Gagal Rate | G6: bulan_file | H6: Order Settled | I6: Order Gagal | J6: Gagal Rate | M6: cancel_source | N6: Order Batal | Q6: metode_analisis | R6: Order Settled | S6: Order Gagal | T6: Gagal Rate | W6: kategori_analisis | X6: Order Settled | Y6: Order Gagal | Z6: Gagal Rate | AC6: alasan_standar | AD6: Order Batal
B7: 20154 | C7: 2835 | D7: 0.14066687 | G7: 2024-01 | H7: 431 | I7: 64 | J7: 0.14849188 | M7: Pembeli | N7: 1844 | Q7: Indomaret/i.Saku | R7: 42 | S7: 21 | T7: 0.5 | W7: Pengolah Bumbu / Sayur | X7: 155 | Y7: 50 | Z7: 0.32258065 | AC7: Ubah pesanan | AD7: 644
G8: 2024-02 | H8: 389 | I8: 63 | J8: 0.16195373 | M8: Penjual (Manual) | N8: 14 | Q8: Alfamart/Alfamidi/Dan+Dan | R8: 35 | S8: 16 | T8: 0.45714286 | W8: Rak / Rak Serbaguna | X8: 568 | Y8: 181 | Z8: 0.31866197 | AC8: Berubah pikiran | AD8: 639
G9: 2024-03 | H9: 453 | I9: 64 | J9: 0.14128035 | M9: Sistem/Penjual (Otomatis) | N9: 880 | Q9: Online Payment | R9: 3079 | S9: 583 | T9: 0.18934719 | W9: Stempel / Alat Kantor | X9: 117 | Y9: 30 | Z9: 0.25641026 | AC9: Belum dibayar | AD9: 431
G10: 2024-04 | H10: 492 | I10: 90 | J10: 0.18292683 | M10: Grand Total | N10: 2738 | Q10: SPayLater | R10: 1443 | S10: 225 | T10: 0.15592516 | W10: Piring | X10: 141 | Y10: 35 | Z10: 0.24822695 | AC10: Ubah alamat | AD10: 379
G11: 2024-05 | H11: 620 | I11: 97 | J11: 0.15645161 | Q11: Kartu Kredit/Debit | R11: 222 | S11: 32 | T11: 0.14414414 | W11: Plastik / Wadah Plastik | X11: 107 | Y11: 26 | Z11: 0.24299065 | AC11: Pengiriman gagal | AD11: 247
G12: 2024-06 | H12: 697 | I12: 89 | J12: 0.1276901 | Q12: COD (Bayar di Tempat) | R12: 11160 | S12: 1543 | T12: 0.13826165
G13: 2024-07 | H13: 1270 | I13: 157 | J13: 0.12362205 | Q13: SeaBank Bayar Instan | R13: 577 | S13: 76 | T13: 0.13171577
G14: 2024-08 | H14: 1293 | I14: 200 | J14: 0.15467904 | Q14: Saldo ShopeePay | R14: 3571 | S14: 336 | T14: 0.094091291
G15: 2024-09 | H15: 1123 | I15: 162 | J15: 0.14425646
G16: 2024-10 | H16: 1217 | I16: 165 | J16: 0.13557929
G17: 2024-11 | H17: 1037 | I17: 148 | J17: 0.14271938
G18: 2024-12 | H18: 1214 | I18: 173 | J18: 0.14250412
G19: 2025-01 | H19: 1150 | I19: 153 | J19: 0.13304348
G20: 2025-02 | H20: 957 | I20: 130 | J20: 0.13584117
G21: 2025-03 | H21: 628 | I21: 116 | J21: 0.18471338
G22: 2025-04 | H22: 824 | I22: 148 | J22: 0.17961165
G23: 2025-05 | H23: 819 | I23: 181 | J23: 0.22100122
G24: 2025-06 | H24: 615 | I24: 100 | J24: 0.16260163
G25: 2025-07 | H25: 766 | I25: 93 | J25: 0.12140992
G26: 2025-08 | H26: 942 | I26: 90 | J26: 0.095541401
... G30: Grand Total | H30: 20154 | I30: 2835 | J30: 0.14066687

Sheet data
A1: order_id | B1: bulan_file | C1: tahun | D1: bulan | E1: status_efektif | F1: is_settled | G1: is_gagal_revenue | H1: is_cancelled | I1: cancel_source | J1: alasan_standar | K1: is_returned | L1: return_type | M1: metode_pembayaran | N1: metode_analisis | O1: jumlah_kategori_berbeda | P1: daftar_kategori | Q1: kategori_analisis | R1: is_artefak_kirim
A2: ORD_0006556 | B2: 2024-01 | C2: 2024 | D2: 36540 | E2: Selesai | F2: 1 | G2: 0 | H2: 0 | I2: Tidak Batal | K2: 0 | L2: Tidak Retur | M2: Saldo ShopeePay | N2: Saldo ShopeePay | O2: 1 | P2: Aksesoris ID Card | Q2: Aksesoris ID Card | R2: 0
A3: ORD_0006557 | B3: 2024-01 | C3: 2024 | D3: 36540 | E3: Selesai | F3: 1 | G3: 0 | H3: 0 | I3: Tidak Batal | K3: 0 | L3: Tidak Retur | M3: COD (Bayar di Tempat) | N3: COD (Bayar di Tempat) | O3: 1 | P3: Celengan | Q3: Celengan | R3: 0
A4: ORD_0006558 | B4: 2024-01 | C4: 2024 | D4: 36540 | E4: Selesai | F4: 1 | G4: 0 | H4: 0 | I4: Tidak Batal | K4: 0 | L4: Tidak Retur | M4: COD (Bayar di Tempat) | N4: COD (Bayar di Tempat) | O4: 1 | P4: Plastik / Wadah Plastik | Q4: Plastik / Wadah Plastik | R4: 0
A5: ORD_0006559 | B5: 2024-01 | C5: 2024 | D5: 36540 | E5: Selesai | F5: 1 | G5: 0 | H5: 0 | I5: Tidak Batal | K5: 0 | L5: Tidak Retur | M5: COD (Bayar di Tempat) | N5: COD (Bayar di Tempat) | O5: 1 | P5: Rak / Rak Serbaguna | Q5: Rak / Rak Serbaguna | R5: 0
A6: ORD_0006560 | B6: 2024-01 | C6: 2024 | D6: 36540 | E6: Selesai | F6: 1 | G6: 0 | H6: 0 | I6: Tidak Batal | K6: 0 | L6: Tidak Retur | M6: Online Payment | N6: Online Payment | O6: 1 | P6: Celengan | Q6: Celengan | R6: 0
A7: ORD_0006561 | B7: 2024-01 | C7: 2024 | D7: 36540 | E7: Selesai | F7: 1 | G7: 0 | H7: 0 | I7: Tidak Batal | K7: 0 | L7: Tidak Retur | M7: SeaBank Bayar Instan | N7: SeaBank Bayar Instan | O7: 1 | P7: Celengan | Q7: Celengan | R7: 0
A8: ORD_0006562 | B8: 2024-01 | C8: 2024 | D8: 36540 | E8: Batal | F8: 1 | G8: 1 | H8: 1 | I8: Pembeli | J8: Berubah pikiran | K8: 0 | L8: Tidak Retur | M8: COD (Bayar di Tempat) | N8: COD (Bayar di Tempat) | O8: 1 | P8: Mangkok Sambal / Saus | Q8: Mangkok Sambal / Saus | R8: 0
A9: ORD_0006563 | B9: 2024-01 | C9: 2024 | D9: 36540 | E9: Batal | F9: 1 | G9: 1 | H9: 1 | I9: Pembeli | J9: Ubah pesanan | K9: 0 | L9: Tidak Retur | M9: COD (Bayar di Tempat) | N9: COD (Bayar di Tempat) | O9: 1 | P9: Rak / Rak Serbaguna | Q9: Rak / Rak Serbaguna | R9: 0
A10: ORD_0006564 | B10: 2024-01 | C10: 2024 | D10: 36540 | E10: Selesai | F10: 1 | G10: 0 | H10: 0 | I10: Tidak Batal | K10: 0 | L10: Tidak Retur | M10: COD (Bayar di Tempat) | N10: COD (Bayar di Tempat) | O10: 1 | P10: Celengan | Q10: Celengan | R10: 0
A11: ORD_0006565 | B11: 2024-01 | C11: 2024 | D11: 36540 | E11: Selesai | F11: 1 | G11: 0 | H11: 0 | I11: Tidak Batal | K11: 0 | L11: Tidak Retur | M11: COD (Bayar di Tempat) | N11: COD (Bayar di Tempat) | O11: 1 | P11: Keranjang | Q11: Keranjang | R11: 0
A12: ORD_0006566 | B12: 2024-01 | C12: 2024 | D12: 36540 | E12: Selesai | F12: 1 | G12: 0 | H12: 0 | I12: Tidak Batal | K12: 0 | L12: Tidak Retur | M12: SPayLater | N12: SPayLater | O12: 2 | P12: Mangkok Sambal / Saus, Peralatan Makan | R12: 0
A13: ORD_0006567 | B13: 2024-01 | C13: 2024 | D13: 36540 | E13: Selesai | F13: 1 | G13: 0 | H13: 0 | I13: Tidak Batal | K13: 0 | L13: Tidak Retur | M13: COD (Bayar di Tempat) | N13: COD (Bayar di Tempat) | O13: 1 | P13: Keranjang | Q13: Keranjang | R13: 0
A14: ORD_0006568 | B14: 2024-01 | C14: 2024 | D14: 36540 | E14: Selesai | F14: 1 | G14: 0 | H14: 0 | I14: Tidak Batal | K14: 0 | L14: Tidak Retur | M14: Online Payment | N14: Online Payment | O14: 1 | P14: Celengan | Q14: Celengan | R14: 0
A15: ORD_0006569 | B15: 2024-01 | C15: 2024 | D15: 36540 | E15: Selesai | F15: 1 | G15: 0 | H15: 0 | I15: Tidak Batal | K15: 0 | L15: Tidak Retur | M15: COD (Bayar di Tempat) | N15: COD (Bayar di Tempat) | O15: 1 | P15: Rak / Rak Serbaguna | Q15: Rak / Rak Serbaguna | R15: 0
A16: ORD_0006570 | B16: 2024-01 | C16: 2024 | D16: 36540 | E16: Selesai | F16: 1 | G16: 0 | H16: 0 | I16: Tidak Batal | K16: 0 | L16: Tidak Retur | M16: COD (Bayar di Tempat) | N16: COD (Bayar di Tempat) | O16: 1 | P16: Botol / Gelas / Mug | Q16: Botol / Gelas / Mug | R16: 0
A17: ORD_0006571 | B17: 2024-01 | C17: 2024 | D17: 36540 | E17: Selesai | F17: 1 | G17: 0 | H17: 0 | I17: Tidak Batal | K17: 0 | L17: Tidak Retur | M17: COD (Bayar di Tempat) | N17: COD (Bayar di Tempat) | O17: 1 | P17: Mangkok Sambal / Saus | Q17: Mangkok Sambal / Saus | R17: 0
A18: ORD_0006572 | B18: 2024-01 | C18: 2024 | D18: 36540 | E18: Selesai | F18: 1 | G18: 0 | H18: 0 | I18: Tidak Batal | K18: 0 | L18: Tidak Retur | M18: COD (Bayar di Tempat) | N18: COD (Bayar di Tempat) | O18: 1 | P18: Celengan | Q18: Celengan | R18: 0
A19: ORD_0006573 | B19: 2024-01 | C19: 2024 | D19: 36540 | E19: Selesai | F19: 1 | G19: 0 | H19: 0 | I19: Tidak Batal | K19: 0 | L19: Tidak Retur | M19: Saldo ShopeePay | N19: Saldo ShopeePay | O19: 1 | P19: Keranjang | Q19: Keranjang | R19: 0
A20: ORD_0006574 | B20: 2024-01 | C20: 2024 | D20: 36540 | E20: Selesai | F20: 1 | G20: 0 | H20: 0 | I20: Tidak Batal | K20: 0 | L20: Tidak Retur | M20: Saldo ShopeePay | N20: Saldo ShopeePay | O20: 1 | P20: Celengan | Q20: Celengan | R20: 0
A21: ORD_0006575 | B21: 2024-01 | C21: 2024 | D21: 36540 | E21: Selesai | F21: 1 | G21: 0 | H21: 0 | I21: Tidak Batal | K21: 0 | L21: Tidak Retur | M21: SeaBank Bayar Instan | N21: SeaBank Bayar Instan | O21: 1 | P21: Celengan | Q21: Celengan | R21: 0
A22: ORD_0006576 | B22: 2024-01 | C22: 2024 | D22: 36540 | E22: Selesai | F22: 1 | G22: 0 | H22: 0 | I22: Tidak Batal | K22: 0 | L22: Tidak Retur | M22: Saldo ShopeePay | N22: Saldo ShopeePay | O22: 1 | P22: Mangkok Sambal / Saus | Q22: Mangkok Sambal / Saus | R22: 0
A23: ORD_0006577 | B23: 2024-01 | C23: 2024 | D23: 36540 | E23: Selesai | F23: 1 | G23: 0 | H23: 0 | I23: Tidak Batal | K23: 0 | L23: Tidak Retur | M23: COD (Bayar di Tempat) | N23: COD (Bayar di Tempat) | O23: 1 | P23: Mangkok Sambal / Saus | Q23: Mangkok Sambal / Saus | R23: 0
A24: ORD_0006578 | B24: 2024-01 | C24: 2024 | D24: 36540 | E24: Batal | F24: 1 | G24: 1 | H24: 1 | I24: Pembeli | J24: Ubah alamat | K24: 0 | L24: Tidak Retur | M24: Saldo ShopeePay | N24: Saldo ShopeePay | O24: 6 | P24: Keranjang, Other, Peralatan Makan, Pisau / Alat Potong, Plastik / Wadah Plastik, Spatula | R24: 1
A25: ORD_0006579 | B25: 2024-01 | C25: 2024 | D25: 36540 | E25: Selesai | F25: 1 | G25: 0 | H25: 0 | I25: Tidak Batal | K25: 0 | L25: Tidak Retur | M25: Saldo ShopeePay | N25: Saldo ShopeePay | O25: 1 | P25: Celengan | Q25: Celengan | R25: 0
A26: ORD_0006580 | B26: 2024-01 | C26: 2024 | D26: 36540 | E26: Selesai | F26: 1 | G26: 0 | H26: 0 | I26: Tidak Batal | K26: 0 | L26: Tidak Retur | M26: COD (Bayar di Tempat) | N26: COD (Bayar di Tempat) | O26: 3 | P26: Celengan, Plastik / Wadah Plastik, Teko / Jug | R26: 0
A27: ORD_0006581 | B27: 2024-01 | C27: 2024 | D27: 36540 | E27: Selesai | F27: 1 | G27: 0 | H27: 0 | I27: Tidak Batal | K27: 0 | L27: Tidak Retur | M27: Saldo ShopeePay | N27: Saldo ShopeePay | O27: 1 | P27: Celengan | Q27: Celengan | R27: 0
A28: ORD_0006582 | B28: 2024-01 | C28: 2024 | D28: 36540 | E28: Selesai | F28: 1 | G28: 0 | H28: 0 | I28: Tidak Batal | K28: 0 | L28: Tidak Retur | M28: Saldo ShopeePay | N28: Saldo ShopeePay | O28: 1 | P28: Celengan | Q28: Celengan | R28: 0
A29: ORD_0006583 | B29: 2024-01 | C29: 2024 | D29: 36540 | E29: Selesai | F29: 1 | G29: 0 | H29: 0 | I29: Tidak Batal | K29: 0 | L29: Tidak Retur | M29: COD (Bayar di Tempat) | N29: COD (Bayar di Tempat) | O29: 1 | P29: Celengan | Q29: Celengan | R29: 0
A30: ORD_0006584 | B30: 2024-01 | C30: 2024 | D30: 36540 | E30: Batal | F30: 1 | G30: 1 | H30: 1 | I30: Pembeli | J30: Lainnya (pembeli) | K30: 0 | L30: Tidak Retur | M30: Saldo ShopeePay | N30: Saldo ShopeePay | O30: 1 | P30: Celengan | Q30: Celengan | R30: 1
A31: ORD_0006585 | B31: 2024-01 | C31: 2024 | D31: 36540 | E31: Selesai | F31: 1 | G31: 0 | H31: 0 | I31: Tidak Batal | K31: 0 | L31: Tidak Retur | M31: Saldo ShopeePay | N31: Saldo ShopeePay | O31: 1 | P31: Celengan | Q31: Celengan | R31: 0
A32: ORD_0006586 | B32: 2024-01 | C32: 2024 | D32: 36540 | E32: Selesai | F32: 1 | G32: 0 | H32: 0 | I32: Tidak Batal | K32: 0 | L32: Tidak Retur | M32: COD (Bayar di Tempat) | N32: COD (Bayar di Tempat) | O32: 1 | P32: Seal / Baut / Roof | Q32: Seal / Baut / Roof | R32: 0
A33: ORD_0006587 | B33: 2024-01 | C33: 2024 | D33: 36540 | E33: Selesai | F33: 1 | G33: 0 | H33: 0 | I33: Tidak Batal | K33: 0 | L33: Tidak Retur | M33: SPayLater | N33: SPayLater | O33: 7 | P33: Botol / Gelas / Mug, Cobek / Ulekan, Mangkok Sambal / Saus, Other, Peralatan Makan, Plastik / Wadah Plastik, Tempat Nasi | R33: 0
A34: ORD_0006588 | B34: 2024-01 | C34: 2024 | D34: 36540 | E34: Selesai | F34: 1 | G34: 0 | H34: 0 | I34: Tidak Batal | K34: 0 | L34: Tidak Retur | M34: COD (Bayar di Tempat) | N34: COD (Bayar di Tempat) | O34: 1 | P34: Nampan / Tray | Q34: Nampan / Tray | R34: 0
A35: ORD_0006589 | B35: 2024-01 | C35: 2024 | D35: 36540 | E35: Selesai | F35: 1 | G35: 0 | H35: 0 | I35: Tidak Batal | K35: 0 | L35: Tidak Retur | M35: Saldo ShopeePay | N35: Saldo ShopeePay | O35: 1 | P35: Peralatan Kamar Mandi | Q35: Peralatan Kamar Mandi | R35: 0
A36: ORD_0006590 | B36: 2024-01 | C36: 2024 | D36: 36540 | E36: Selesai | F36: 1 | G36: 0 | H36: 0 | I36: Tidak Batal | K36: 0 | L36: Tidak Retur | M36: Saldo ShopeePay | N36: Saldo ShopeePay | O36: 1 | P36: Saringan / Strainer | Q36: Saringan / Strainer | R36: 0
A37: ORD_0006591 | B37: 2024-01 | C37: 2024 | D37: 36540 | E37: Batal | F37: 1 | G37: 1 | H37: 1 | I37: Pembeli | J37: Ubah pesanan | K37: 0 | L37: Tidak Retur | M37: Kartu Kredit/Debit | N37: Kartu Kredit/Debit | O37: 1 | P37: Celengan | Q37: Celengan | R37: 0
A38: ORD_0006592 | B38: 2024-01 | C38: 2024 | D38: 36540 | E38: Selesai | F38: 1 | G38: 0 | H38: 0 | I38: Tidak Batal | K38: 0 | L38: Tidak Retur | M38: Kartu Kredit/Debit | N38: Kartu Kredit/Debit | O38: 1 | P38: Celengan | Q38: Celengan | R38: 0
A39: ORD_0006593 | B39: 2024-01 | C39: 2024 | D39: 36540 | E39: Selesai | F39: 1 | G39: 0 | H39: 0 | I39: Tidak Batal | K39: 0 | L39: Tidak Retur | M39: COD (Bayar di Tempat) | N39: COD (Bayar di Tempat) | O39: 1 | P39: Rak / Rak Serbaguna | Q39: Rak / Rak Serbaguna | R39: 0
A40: ORD_0006594 | B40: 2024-01 | C40: 2024 | D40: 36540 | E40: Selesai | F40: 1 | G40: 0 | H40: 0 | I40: Tidak Batal | K40: 0 | L40: Tidak Retur | M40: COD (Bayar di Tempat) | N40: COD (Bayar di Tempat) | O40: 1 | P40: Celengan | Q40: Celengan | R40: 0
...
